<robot
  name="mx_urdf">
  <link
    name="base_link">
    <inertial>
      <origin
        xyz="-0.014505 8.3409E-05 0.1046"
        rpy="0 0 0" />
      <mass
        value="2.6444" />
      <inertia
        ixx="0.033044"
        ixy="3.9355E-05"
        ixz="0.00015077"
        iyy="0.035221"
        iyz="7.7344E-05"
        izz="0.022469" />
    </inertial>
    <visual>
      <origin
        xyz="0 0 0"
        rpy="0 0 0" />
      <geometry>
        <mesh
          filename="package://mx_urdf/meshes/base_link.STL" />
      </geometry>
      <material
        name="">
        <color
          rgba="0.29804 0.29804 0.29804 1" />
      </material>
    </visual>
    <collision>
      <origin
        xyz="0 0 0"
        rpy="0 0 0" />
      <geometry>
        <mesh
          filename="package://mx_urdf/meshes/base_link.STL" />
      </geometry>
    </collision>
  </link>
  <link
    name="left_wheel_link">
    <inertial>
      <origin
        xyz="-0.0227829096954315 3.22519788653608E-14 1.33434929772136E-14"
        rpy="0 0 0" />
      <mass
        value="0.318362055265437" />
      <inertia
        ixx="0.000642282496408127"
        ixy="-4.30889728137452E-16"
        ixz="-1.78057602259983E-16"
        iyy="0.000338397819689947"
        iyz="3.3881317890172E-20"
        izz="0.000338397819689947" />
    </inertial>
    <visual>
      <origin
        xyz="0 0 0"
        rpy="0 0 0" />
      <geometry>
        <mesh
          filename="package://mx_urdf/meshes/left_wheel_link.STL" />
      </geometry>
      <material
        name="">
        <color
          rgba="0.298039215686275 0.298039215686275 0.298039215686275 1" />
      </material>
    </visual>
    <collision>
      <origin
        xyz="0 0 0"
        rpy="0 0 0" />
      <geometry>
        <mesh
          filename="package://mx_urdf/meshes/left_wheel_link.STL" />
      </geometry>
    </collision>
  </link>
  <joint
    name="left_wheel"
    type="continuous">
    <origin
      xyz="0 0.132 -0.024"
      rpy="2.74979624140029 5.90138314899544E-39 -1.57079632679643" />
    <parent
      link="base_link" />
    <child
      link="left_wheel_link" />
    <axis
      xyz="-1 0 0" />
  </joint>
  <link
    name="right_wheel_link">
    <inertial>
      <origin
        xyz="-0.0227829096954314 0 5.5122573172639E-14"
        rpy="0 0 0" />
      <mass
        value="0.318362055265437" />
      <inertia
        ixx="0.000642282496408127"
        ixy="-3.72700024625838E-24"
        ixz="-3.43339642935429E-21"
        iyy="0.000338397819689947"
        iyz="8.78879400837592E-22"
        izz="0.000338397819689947" />
    </inertial>
    <visual>
      <origin
        xyz="0 0 0"
        rpy="0 0 0" />
      <geometry>
        <mesh
          filename="package://mx_urdf/meshes/right_wheel_link.STL" />
      </geometry>
      <material
        name="">
        <color
          rgba="0.298039215686275 0.298039215686275 0.298039215686275 1" />
      </material>
    </visual>
    <collision>
      <origin
        xyz="0 0 0"
        rpy="0 0 0" />
      <geometry>
        <mesh
          filename="package://mx_urdf/meshes/right_wheel_link.STL" />
      </geometry>
    </collision>
  </link>
  <joint
    name="right_wheel"
    type="continuous">
    <origin
      xyz="0 -0.132 -0.024"
      rpy="1.5707963267949 -5.90138314899544E-39 1.57079632679337" />
    <parent
      link="base_link" />
    <child
      link="right_wheel_link" />
    <axis
      xyz="1 0 0" />
  </joint>
  <link
    name="lidar_link">
    <inertial>
      <origin
        xyz="-0.00116439147312708 4.41207015366984E-10 0.0189284573767456"
        rpy="0 0 0" />
      <mass
        value="0.148482326477962" />
      <inertia
        ixx="6.853078563179E-05"
        ixy="3.3222758559798E-13"
        ixz="1.3906754711892E-06"
        iyy="6.54042842831122E-05"
        iyz="-3.02067741558941E-12"
        izz="9.41338978203851E-05" />
    </inertial>
    <visual>
      <origin
        xyz="0 0 0"
        rpy="0 0 0" />
      <geometry>
        <mesh
          filename="package://mx_urdf/meshes/lidar_link.STL" />
      </geometry>
      <material
        name="">
        <color
          rgba="1 1 1 1" />
      </material>
    </visual>
    <collision>
      <origin
        xyz="0 0 0"
        rpy="0 0 0" />
      <geometry>
        <mesh
          filename="package://mx_urdf/meshes/lidar_link.STL" />
      </geometry>
    </collision>
  </link>
  <joint
    name="lidar"
    type="fixed">
    <origin
      xyz="0 0 0.058"
      rpy="5.90138314899544E-39 -6.28689575958092E-39 -1.53144402893157E-12" />
    <parent
      link="base_link" />
    <child
      link="lidar_link" />
    <axis
      xyz="0 0 0" />
  </joint>
  <link
    name="camera_link">
    <inertial>
      <origin
        xyz="0.00399310539547737 0.0025570449458408 0.000513929215761877"
        rpy="0 0 0" />
      <mass
        value="0.0192165264496676" />
      <inertia
        ixx="2.76975918992374E-05"
        ixy="-4.88427257529534E-09"
        ixz="4.04259233429922E-10"
        iyy="7.23354486633329E-07"
        iyz="3.27508784952214E-07"
        izz="2.71788392198576E-05" />
    </inertial>
    <visual>
      <origin
        xyz="0 0 0"
        rpy="0 0 0" />
      <geometry>
        <mesh
          filename="package://mx_urdf/meshes/camera_link.STL" />
      </geometry>
      <material
        name="">
        <color
          rgba="0.00784313725490196 0.23921568627451 0.823529411764706 1" />
      </material>
    </visual>
    <collision>
      <origin
        xyz="0 0 0"
        rpy="0 0 0" />
      <geometry>
        <mesh
          filename="package://mx_urdf/meshes/camera_link.STL" />
      </geometry>
    </collision>
  </link>
  <joint
    name="camera"
    type="fixed">
    <origin
      xyz="-0.105000000000172 0.00100000000031975 0.376"
      rpy="5.90138314899544E-39 -6.28689575958092E-39 -1.53144402893157E-12" />
    <parent
      link="base_link" />
    <child
      link="camera_link" />
    <axis
      xyz="0 0 0" />
  </joint>
  <link
    name="front_omni_link">
    <inertial>
      <origin
        xyz="0.0105221599223845 -0.00648600883647715 -0.012111610695899"
        rpy="0 0 0" />
      <mass
        value="0.00460045407648726" />
      <inertia
        ixx="1.26580886503005E-06"
        ixy="-1.50891620470604E-07"
        ixz="1.35149232985841E-07"
        iyy="1.11403127257408E-06"
        iyz="-8.33079069179048E-08"
        izz="1.08583675414323E-06" />
    </inertial>
    <visual>
      <origin
        xyz="0 0 0"
        rpy="0 0 0" />
      <geometry>
        <mesh
          filename="package://mx_urdf/meshes/front_omni_link.STL" />
      </geometry>
      <material
        name="">
        <color
          rgba="0.776470588235294 0.756862745098039 0.737254901960784 1" />
      </material>
    </visual>
    <collision>
      <origin
        xyz="0 0 0"
        rpy="0 0 0" />
      <geometry>
        <mesh
          filename="package://mx_urdf/meshes/front_omni_link.STL" />
      </geometry>
    </collision>
  </link>
  <joint
    name="front_omni"
    type="continuous">
    <origin
      xyz="0.109000000000001 0 -0.034"
      rpy="-5.0560979501588E-39 -6.98478738985546E-39 1.38034790661819" />
    <parent
      link="base_link" />
    <child
      link="front_omni_link" />
    <axis
      xyz="0 0 1" />
  </joint>
  <link
    name="front_omni_wheel_link">
    <inertial>
      <origin
        xyz="0 -0.000500000000000278 0"
        rpy="0 0 0" />
      <mass
        value="0.0201268954931076" />
      <inertia
        ixx="2.27266447785936E-06"
        ixy="1.21760986167806E-21"
        ixz="6.61744490042422E-23"
        iyy="3.38154229218006E-06"
        iyz="-3.70576914423756E-21"
        izz="2.27266447785936E-06" />
    </inertial>
    <visual>
      <origin
        xyz="0 0 0"
        rpy="0 0 0" />
      <geometry>
        <mesh
          filename="package://mx_urdf/meshes/front_omni_wheel_link.STL" />
      </geometry>
      <material
        name="">
        <color
          rgba="0.298039215686275 0.298039215686275 0.298039215686275 1" />
      </material>
    </visual>
    <collision>
      <origin
        xyz="0 0 0"
        rpy="0 0 0" />
      <geometry>
        <mesh
          filename="package://mx_urdf/meshes/front_omni_wheel_link.STL" />
      </geometry>
    </collision>
  </link>
  <joint
    name="front_omni_wheel"
    type="continuous">
    <origin
      xyz="0.0144715368252966 -0.00892046085771814 -0.0344999999999997"
      rpy="0 -1.34064070369349 2.58919123082909" />
    <parent
      link="front_omni_link" />
    <child
      link="front_omni_wheel_link" />
    <axis
      xyz="0 1 0" />
  </joint>
  <link
    name="back_omni_link">
    <inertial>
      <origin
        xyz="0.00913809784585118 -0.00832342043986309 -0.012111610695899"
        rpy="0 0 0" />
      <mass
        value="0.00460045407648728" />
      <inertia
        ixx="1.20564614471213E-06"
        ixy="-1.68166825080479E-07"
        ixz="1.17371996237111E-07"
        iyy="1.17419399289201E-06"
        iyz="-1.06908077482571E-07"
        izz="1.08583675414324E-06" />
    </inertial>
    <visual>
      <origin
        xyz="0 0 0"
        rpy="0 0 0" />
      <geometry>
        <mesh
          filename="package://mx_urdf/meshes/back_omni_link.STL" />
      </geometry>
      <material
        name="">
        <color
          rgba="0.776470588235294 0.756862745098039 0.737254901960784 1" />
      </material>
    </visual>
    <collision>
      <origin
        xyz="0 0 0"
        rpy="0 0 0" />
      <geometry>
        <mesh
          filename="package://mx_urdf/meshes/back_omni_link.STL" />
      </geometry>
    </collision>
  </link>
  <joint
    name="back_omni"
    type="continuous">
    <origin
      xyz="-0.109 0 -0.034"
      rpy="-9.96547374531681E-40 8.56494452366143E-39 -2.50364478445485" />
    <parent
      link="base_link" />
    <child
      link="back_omni_link" />
    <axis
      xyz="0 0 1" />
  </joint>
  <link
    name="back_omni_wheel_link">
    <inertial>
      <origin
        xyz="0 0.000499999999999723 -1.38777878078145E-17"
        rpy="0 0 0" />
      <mass
        value="0.0201268954931076" />
      <inertia
        ixx="2.27266447785937E-06"
        ixy="8.33798057453452E-22"
        ixz="0"
        iyy="3.38154229218006E-06"
        iyz="7.14684049245816E-22"
        izz="2.27266447785937E-06" />
    </inertial>
    <visual>
      <origin
        xyz="0 0 0"
        rpy="0 0 0" />
      <geometry>
        <mesh
          filename="package://mx_urdf/meshes/back_omni_wheel_link.STL" />
      </geometry>
      <material
        name="">
        <color
          rgba="0.298039215686275 0.298039215686275 0.298039215686275 1" />
      </material>
    </visual>
    <collision>
      <origin
        xyz="0 0 0"
        rpy="0 0 0" />
      <geometry>
        <mesh
          filename="package://mx_urdf/meshes/back_omni_wheel_link.STL" />
      </geometry>
    </collision>
  </link>
  <joint
    name="back_omni_wheel"
    type="continuous">
    <origin
      xyz="0.0125679822835678 -0.0114475246809032 -0.0344999999999994"
      rpy="3.14159265358979 -0.820094510728467 -0.738776383504164" />
    <parent
      link="back_omni_link" />
    <child
      link="back_omni_wheel_link" />
    <axis
      xyz="0 1 0" />
  </joint>
	<gazebo>
	<plugin name="differential_drive_controller" filename="libgazebo_ros_diff_drive.so">
	<alwaysOn>true</alwaysOn>
        <legacyMode>true</legacyMode>
	<updateRate>30.0</updateRate>
	<leftJoint>right_wheel</leftJoint>
	<rightJoint>left_wheel</rightJoint>
	<wheelSeparation>0.31</wheelSeparation>
	<wheelAcceleration>0</wheelAcceleration>      
        <wheelTorque>5</wheelTorque> 	
        <odometrySource>1</odometrySource>
	<publishTf>1</publishTf>
	<wheelDiameter>0.128</wheelDiameter>
        <publishWheelTF>true</publishWheelTF>        
	<publishWheelJointState>true</publishWheelJointState>
	<torque>20</torque>
	<commandTopic>cmd_vel</commandTopic>
	<odometryTopic>odom</odometryTopic>
	<odometryFrame>odom</odometryFrame>
	<robotBaseFrame>base_link</robotBaseFrame>
	</plugin>
        </gazebo>


        <gazebo reference="lidar_link">
        <sensor type="ray" name="laser_sensor">
          <pose>0 0 0 0 0 0</pose>
          <visualize>False</visualize>
          <update_rate>40</update_rate>
          <ray>
            <scan>
              <horizontal>
                <samples>720</samples>
                <resolution>1</resolution>
                <min_angle>-3.14</min_angle>
                <max_angle>3.14</max_angle>
              </horizontal>
            </scan>
            <range>
              <min>0.10</min>
              <max>30.0</max>
              <resolution>0.01</resolution>
            </range>
            <noise>
              <type>gaussian</type>
              <!-- Noise parameters based on published spec for Hokuyo laser
                   achieving "+-30mm" accuracy at range < 10m.  A mean of 0.0m and
                   stddev of 0.01m will put 99.7% of samples within 0.03m of the true
                   reading. -->
              <mean>0.0</mean>
              <stddev>0.01</stddev>
            </noise>
          </ray>
          <plugin name="gazebo_ros_head_hokuyo_controller" filename="libgazebo_ros_laser.so">
            <topicName>/scan</topicName>
            <frameName>lidar_link</frameName>
          </plugin>
        </sensor>
      </gazebo>


     <gazebo reference="camera_link">  
      <sensor type="depth" name="camera">
        <always_on>true</always_on>
        <update_rate>20.0</update_rate>
        <camera>
          <horizontal_fov>${0}</horizontal_fov>
          <image>
            <format>B8G8R8</format>
            <width>640</width>
            <height>480</height>
          </image>
          <clip>
            <near>0.05</near>
            <far>8.0</far>
          </clip>
        </camera>
        <plugin name="kinect_camera_controller" filename="libgazebo_ros_openni_kinect.so">
          <cameraName>camera</cameraName>
          <alwaysOn>true</alwaysOn>
          <updateRate>10</updateRate>
          <imageTopicName>rgb/image_raw</imageTopicName>
          <depthImageTopicName>depth/image_raw</depthImageTopicName>
          <pointCloudTopicName>depth/points</pointCloudTopicName>
          <cameraInfoTopicName>rgb/camera_info</cameraInfoTopicName>
          <depthImageCameraInfoTopicName>depth/camera_info</depthImageCameraInfoTopicName>
          <frameName>camera_link</frameName>
          <baseline>0.1</baseline>
          <distortion_k1>0.0</distortion_k1>
          <distortion_k2>0.0</distortion_k2>
          <distortion_k3>0.0</distortion_k3>
          <distortion_t1>0.0</distortion_t1>
          <distortion_t2>0.0</distortion_t2>
          <pointCloudCutoff>0.4</pointCloudCutoff>
        </plugin>
      </sensor>
    </gazebo>
</robot>
